Workbook

Sheet Lisez-moi
A1: Grille tarifaire Stackup Agency — version de travail du 14/10/2026
A2: Mathéo Reboul · Stackup Agency · document interne, ne pas transmettre tel quel au client
A4: À QUOI SERT CE FICHIER
A5: 1. Il contient le prix de chaque élément qu'on peut te demander : site, pages, niveau d'animation, référencement, boutique, outil de gestion, abonnements, services à la carte.
A6: 2. L'onglet « Simulateur » calcule automatiquement un devis : prix exact, fourchette à afficher au client, temps estimé, taux horaire réel, acompte, abonnement mensuel, délai indicatif.
A7: 3. Les colonnes « Exemple » du simulateur recalculent Hydr'eaux Scan et ToutouBien avec cette grille, pour vérifier que tout est cohérent.
A9: COMMENT L'UTILISER
A10: • Cellules en TEXTE BLEU = valeurs que tu peux modifier (prix, temps, paramètres). Texte noir = formules, ne pas toucher.
A11: • Cellules sur FOND JAUNE = ce qu'on remplit pour chaque projet (onglet Simulateur, colonne « Nouveau projet »).
A12: • Pour monter ou baisser tous tes prix d'un coup : onglet Paramètres, « Coefficient général » (1,00 = grille actuelle ; 1,10 = +10 % partout).
A13: • La colonne « Temps estimé » est une estimation de départ (≈ prix ÷ 50 €/h). Remplace-la par ton vrai temps au fil des projets : la colonne « €/h effectif » te dira si un élément est rentable.
A15: LES 4 NIVEAUX VISUELS (à montrer au client avec un exemple de chaque)
... A31: Document d'aide à la décision, pas un conseil juridique ou fiscal : faire relire CGV et contrats par un professionnel avant usage.

Sheet Simulateur
A1: Simulateur de devis
A2: Fond jaune = à remplir (colonne E pour un nouveau projet). Colonnes C et D : exemples recalculés.
A4: Élément | B4: Code | C4: Exemple : Hydr'eaux Scan | D4: Exemple : ToutouBien | E4: Nouveau projet | F4: Aide
A6: 1. LE SITE
A7: Niveau visuel de la page d'accueil | C7: Immersif | D7: Signature | E7: Classique | F7: Aucun · Classique · Animé · Signature · Immersif
A8: Autres pages en niveau Classique | C8: 0 | D8: 22 | E8: 0 | F8: Nombre de pages (hors pages légales, incluses).
A9: Autres pages en niveau Animé | C9: 23 | D9: 10 | E9: 0
A10: Autres pages en niveau Signature | C10: 6 | D10: 3 | E10: 0
A11: Autres pages en niveau Immersif | C11: 0 | D11: 0 | E11: 0
A12: Pages en série (villes, métiers, produits…) | B12: L02 | C12: 0 | D12: 0 | E12: 0 | F12: Déclinaisons d'un même gabarit.
A13: Total des autres pages | C13: =SUM(C8:C11) -> 29 | D13: =SUM(D8:D11) -> 35 | E13: =SUM(E8:E11) -> 0
A14: Coefficient de dégressivité appliqué | C14: =IF(C13=0,0,(MIN(C13,Paramètres!$B$10)+MAX(0,MIN(C13,Paramètres!$B$11)-Paramètres!$B$10)*Paramètres!$B$12+MAX(0,C13-Paramètres!$B$11)*Paramètres!$B$13)/C13) -> 0.73793103 | D14: =IF(D13=0,0,(MIN(D13,Paramètres!$B$10)+MAX(0,MIN(D13,Paramètres!$B$11)-Paramètres!$B$10)*Paramètres!$B$12+MAX(0,D13-Paramètres!$B$11)*Paramètres!$B$13)/D13) -> 0.68571429 | E14: =IF(E13=0,0,(MIN(E13,Paramètres!$B$10)+MAX(0,MIN(E13,Paramètres!$B$11)-Paramètres!$B$10)*Paramètres!$B$12+MAX(0,E13-Paramètres!$B$11)*Paramètres!$B$13)/E13) -> 0 | F14: Les pages au-delà de 10 sont moins chères (gabarit déjà fait).
A15: Forfait de lancement | C15: ='Création site'!$D$14 -> 300 | D15: ='Création site'!$D$14 -> 300 | E15: ='Création site'!$D$14 -> 300 | F15: Cadrage, mobile, légal, contact, mise en ligne.
A16: Page d'accueil | C16: =INDEX('Création site'!$D$6:$D$10,MATCH(C7,'Création site'!$A$6:$A$10,0)) -> 1400 | D16: =INDEX('Création site'!$D$6:$D$10,MATCH(D7,'Création site'!$A$6:$A$10,0)) -> 900 | E16: =INDEX('Création site'!$D$6:$D$10,MATCH(E7,'Création site'!$A$6:$A$10,0)) -> 200
A17: Autres pages (après dégressivité) | C17: =C14*(C8*'Création site'!$F$7+C9*'Création site'!$F$8+C10*'Création site'!$F$9+C11*'Création site'!$F$10) -> 1505.3793 | D17: =D14*(D8*'Création site'!$F$7+D9*'Création site'!$F$8+D10*'Création site'!$F$9+D11*'Création site'!$F$10) -> 1392 | E17: =E14*(E8*'Création site'!$F$7+E9*'Création site'!$F$8+E10*'Création site'!$F$9+E11*'Création site'!$F$10) -> 0
A18: Pages en série | C18: =C12*'Création site'!$D$15 -> 0 | D18: =D12*'Création site'!$D$15 -> 0 | E18: =E12*'Création site'!$D$15 -> 0
A20: 2. RÉFÉRENCEMENT
A21: Portée du référencement | C21: Essentiel | D21: Local | E21: Aucun | F21: Aucun · Essentiel (nom) · Local (ville) · Régional (département/région) · National (France)
A22: Visibilité dans les IA | C22: Aucune | D22: Aucune | E22: Aucune | F22: Aucune · Essentielle · Avancée
A23: Nombre de pages à référencer | C23: =IF(C7="Aucun",0,1)+C13 -> 30 | D23: =IF(D7="Aucun",0,1)+D13 -> 36 | E23: =IF(E7="Aucun",0,1)+E13 -> 1
A24: Référencement (portée) | C24: =INDEX(Référencement!$D$6:$D$10,MATCH(C21,Référencement!$A$6:$A$10,0))+C23*INDEX(Référencement!$F$6:$F$10,MATCH(C21,Référencement!$A$6:$A$10,0))+C12*INDEX(Référencement!$H$6:$H$10,MATCH(C21,Référencement!$A$6:$A$10,0)) -> 390 | D24: =INDEX(Référencement!$D$6:$D$10,MATCH(D21,Référencement!$A$6:$A$10,0))+D23*INDEX(Référencement!$F$6:$F$10,MATCH(D21,Référencement!$A$6:$A$10,0))+D12*INDEX(Référencement!$H$6:$H$10,MATCH(D21,Référencement!$A$6:$A$10,0)) -> 890 | E24: =INDEX(Référencement!$D$6:$D$10,MATCH(E21,Référencement!$A$6:$A$10,0))+E23*INDEX(Référencement!$F$6:$F$10,MATCH(E21,Référencement!$A$6:$A$10,0))+E12*INDEX(Référencement!$H$6:$H$10,MATCH(E21,Référencement!$A$6:$A$10,0)) -> 0
A25: Visibilité dans les IA | C25: =INDEX(Référencement!$D$14:$D$16,MATCH(C22,Référencement!$A$14:$A$16,0))+C23*INDEX(Référencement!$F$14:$F$16,MATCH(C22,Référencement!$A$14:$A$16,0)) -> 0 | D25: =INDEX(Référencement!$D$14:$D$16,MATCH(D22,Référencement!$A$14:$A$16,0))+D23*INDEX(Référencement!$F$14:$F$16,MATCH(D22,Référencement!$A$14:$A$16,0)) -> 0 | E25: =INDEX(Référencement!$D$14:$D$16,MATCH(E22,Référencement!$A$14:$A$16,0))+E23*INDEX(Référencement!$F$14:$F$16,MATCH(E22,Référencement!$A$14:$A$16,0)) -> 0
A27: 3. FONCTIONNALITÉS
A28: Formulaire avancé | B28: F02 | C28: 1 | D28: 0 | E28: 0
A29: Questionnaire guidé en plusieurs étapes | B29: F03 | C29: 1 | D29: 1 | E29: 0
A30: Prise de rendez-vous (outil existant) | B30: F04 | C30: 0 | D30: 0 | E30: 0
A31: Prise de rendez-vous sur mesure | B31: F05 | C31: 0 | D31: 0 | E31: 0
A32: Blog / actualités | B32: F06 | C32: 0 | D32: 1 | E32: 0
A33: Galerie / portfolio filtrable | B33: F07 | C33: 0 | D33: 1 | E33: 0
A34: FAQ avec recherche | B34: F08 | C34: 1 | D34: 1 | E34: 0
A35: Carte interactive / zone d'intervention | B35: F09 | C35: 0 | D35: 0 | E35: 0
A36: Avis Google affichés | B36: F10 | C36: 0 | D36: 0 | E36: 0
A37: Inscription à une newsletter | B37: F11 | C37: 0 | D37: 0 | E37: 0
A38: Espace membre / client | B38: F12 | C38: 0 | D38: 0 | E38: 0
A39: Paiement en ligne simple | B39: F13 | C39: 0 | D39: 0 | E39: 0
... A46: Fil Instagram / réseaux sociaux | B46: F20 | C46: 0 | D46: 0 | E46: 0
A47: Sous-total fonctionnalités | C47: =C28*'Création site'!$D$18+C29*'Création site'!$D$19+C30*'Création site'!$D$20+C31*'Création site'!$D$21+C32*'Création site'!$D$22+C33*'Création site'!$D$23+C34*'Création site'!$D$24+C35*'Création site'!$D$25+C36*'Création site'!$D$26+C37*'Création site'!$D$27+C38*'Création site'!$D$28+C39*'Création site'!$D$29+C40*'Création site'!$D$30+C41*'Création site'!$D$31+C42*'Création site'!$D$32+C43*'Création site'!$D$33+C44*'Création site'!$D$34+C45*'Création site'!$D$35+C46*'Création site'!$D$36 -> 450 | D47: =D28*'Création site'!$D$18+D29*'Création site'!$D$19+D30*'Création site'!$D$20+D31*'Création site'!$D$21+D32*'Création site'!$D$22+D33*'Création site'!$D$23+D34*'Création site'!$D$24+D35*'Création site'!$D$25+D36*'Création site'!$D$26+D37*'Création site'!$D$27+D38*'Création site'!$D$28+D39*'Création site'!$D$29+D40*'Création site'!$D$30+D41*'Création site'!$D$31+D42*'Création site'!$D$32+D43*'Création site'!$D$33+D44*'Création site'!$D$34+D45*'Création site'!$D$35+D46*'Création site'!$D$36 -> 650 | E47: =E28*'Création site'!$D$18+E29*'Création site'!$D$19+E30*'Création site'!$D$20+E31*'Création site'!$D$21+E32*'Création site'!$D$22+E33*'Création site'!$D$23+E34*'Création site'!$D$24+E35*'Création site'!$D$25+E36*'Création site'!$D$26+E37*'Création site'!$D$27+E38*'Création site'!$D$28+E39*'Création site'!$D$29+E40*'Création site'!$D$30+E41*'Création site'!$D$31+E42*'Création site'!$D$32+E43*'Création site'!$D$33+E44*'Création site'!$D$34+E45*'Création site'!$D$35+E46*'Création site'!$D$36 -> 0
A49: 4. EFFETS SUR MESURE
A50: Scène 3D sur mesure | B50: E01 | C50: 0 | D50: 0 | E50: 0
A51: Démonstration interactive | B51: E02 | C51: 0 | D51: 0 | E51: 0
...

Sheet Paramètres
A1: Paramètres généraux
A2: Les leviers qui s'appliquent à tout le fichier. Texte bleu = modifiable.
A4: Paramètre | B4: Valeur | C4: Explication
A5: Taux horaire cible (€/h) | B5: 45 | C5: Le minimum que tu veux gagner par heure réelle. Sert de repère pour la colonne « €/h effectif ».
A6: Coefficient général des prix | B6: 1 | C6: 1,00 = grille actuelle. Multiplie toute la création ET les abonnements.
A7: Fourchette affichée : bas | B7: 0.9 | C7: Le site affiche « entre bas × prix et haut × prix ».
A8: Fourchette affichée : haut | B8: 1.15
A9: Arrondi des prix (€) | B9: 10 | C9: Tous les totaux sont arrondis à ce montant.
A10: Dégressivité : pages au plein tarif jusqu'à | B10: 10 | C10: Les premières pages intérieures sont facturées 100 %.
A11: Dégressivité : 2e tranche jusqu'à | B11: 30
A12: Dégressivité : taux de la 2e tranche | B12: 0.6 | C12: Pages 11 à 30 facturées à 60 % (le gabarit est déjà fait).
A13: Dégressivité : taux au-delà | B13: 0.4 | C13: Pages 31+ facturées à 40 %.
A14: Acompte à la signature | B14: 0.4 | C14: Comme dans tes devis actuels.
A15: Majoration délai accéléré | B15: 0.2 | C15: Si le client veut le site plus vite que le délai indicatif.
A16: Heures disponibles par semaine | B16: 15 | C16: Ton temps réel de production (cours compris). Sert au délai indicatif.
A17: Coefficient d'attente client | B17: 1.6 | C17: Le délai réel s'allonge à cause des retours, contenus, validations.
A18: Paiement en 4 fois possible à partir de | B18: 3000
A19: Nombre de catégories boutique incluses | B19: 5

Sheet Parcours client
A1: Parcours avant et pendant le projet
A2: Ce que le client vit avant de signer, et ce qui est inclus pendant la création.
A4: Code | B4: Élément | C4: Ce que ça veut dire pour le client | D4: Prix (€) | E4: Temps estimé (h) | F4: €/h effectif | G4: Unité | H4: Note interne
A5: AVANT LA SIGNATURE
A6: P01 | B6: Appel découverte (30 min) | C6: Un appel pour comprendre qui vous êtes, votre activité et ce que vous attendez. Gratuit, sans engagement. | D6: 0 | E6: 0.5 | F6: =IF(E6>0,D6/E6,"") -> 0 | G6: forfait | H6: Gratuit. Sert à qualifier le projet avant la démo.
A7: P02 | B7: Démo de votre future page d'accueil | C7: On réalise la page d'accueil de votre site, à votre image, pour que vous puissiez juger sur pièce avant de décider. | D7: 15 | E7: 6 | F7: =IF(E7>0,D7/E7,"") -> 2.5 | G7: forfait | H7: 15 € ; offerte à ta discrétion. NON déduite du devis (ne pas le préciser au client). Plafond conseillé : ~6 h de travail.
A8: P03 | B8: Visio de présentation et conseil (1 h 30) | C8: On vous présente la démo, on échange sur vos besoins, on vous conseille et on ajuste le projet et le prix ensemble. | D8: 30 | E8: 1.5 | F8: =IF(E8>0,D8/E8,"") -> 20 | G8: forfait | H8: 30 € ; NON déduite du devis (ne pas le préciser au client).
A9: PENDANT LA CRÉATION (inclus dans le devis)
A10: P04 | B10: Rendez-vous de finalisation inclus | C10: Rendez-vous (visio ou sur place) pour construire le site avec vous. | D10: 0 | E10: 0 | F10: =IF(E10>0,D10/E10,"") | G10: 3 inclus | H10: Au-delà : P05.
A11: P05 | B11: Rendez-vous supplémentaire (1 h) | C11: Un rendez-vous de plus que ceux prévus. | D11: 40 | E11: 1 | F11: =IF(E11>0,D11/E11,"") -> 40 | G11: par heure
A12: P06 | B12: Séries de modifications sur la maquette | C12: Deux séries de retours complets sur le design sont incluses avant le développement final. | D12: 0 | E12: 0 | F12: =IF(E12>0,D12/E12,"") | G12: 2 incluses | H12: Au-delà : 40 €/h.
A13: P07 | B13: Mois d'ajustements après la mise en ligne | C13: Pendant un mois, les petites modifications du périmètre prévu sont gratuites. | D13: 0 | E13: 0 | F13: =IF(E13>0,D13/E13,"") | G13: inclus
A14: P08 | B14: Déplacement | C14: Gratuit jusqu'à 40 km de Savigné-sur-Lathan. | D14: 0.5 | E14: 0 | F14: =IF(E14>0,D14/E14,"") | G14: par km (A/R) au-delà de 40 km

Sheet Création site
A1: Création de site : niveaux, pages, fonctionnalités, effets, contenus
A2: Le cœur de la grille. Les prix de niveau sont lus par le Simulateur.
A4: NIVEAUX VISUELS (le niveau se choisit pour l'accueil et pour chaque autre page)
A5: Niveau | B5: Description pour le client | D5: Accueil (€) | E5: Accueil (h) | F5: Page intérieure (€) | G5: Page intérieure (h) | H5: Exemple
A6: Aucun | B6: Pas de site (outil de gestion seul). | D6: 0 | E6: 0 | F6: 0 | G6: 0
A7: Classique | B7: Mise en page soignée et personnalisée, sans animation. | D7: 200 | E7: 4 | F7: 50 | G7: 1 | H7: Site vitrine d'artisan simple
A8: Animé | B8: Apparitions douces au défilement, survols, petites animations qui donnent de la vie. | D8: 450 | E8: 8 | F8: 60 | G8: 1.25 | H8: Site de commerce moderne
A9: Signature | B9: Vraie mise en scène, effets marquants et interactions : un site dont on se souvient. | D9: 900 | E9: 14 | F9: 110 | G9: 2 | H9: ToutouBien
A10: Immersif | B10: Univers 3D animé en continu, comme stackup-agency.fr. | D10: 1400 | E10: 22 | F10: 220 | G10: 4 | H10: Hydr'eaux Scan, stackup-agency.fr
A12: Code | B12: Élément | C12: Ce que ça veut dire pour le client | D12: Prix (€) | E12: Temps estimé (h) | F12: €/h effectif | G12: Unité | H12: Note interne
A13: BASE DE TOUT PROJET
A14: L01 | B14: Forfait de lancement | C14: Cadrage, structure du site, adaptation mobile et tablette, mentions légales et confidentialité, formulaire de contact, mise en ligne, tests. | D14: 300 | E14: 6 | F14: =IF(E14>0,D14/E14,"") -> 50 | G14: par projet | H14: Toujours compté.
A15: L02 | B15: Page en série (déclinaison d'un gabarit) | C15: Pages générées à partir d'un même modèle : une par ville, par métier, par produit… (le modèle lui-même compte comme une page). | D15: 20 | E15: 0.4 | F15: =IF(E15>0,D15/E15,"") -> 50 | G15: par page
A16: FONCTIONNALITÉS
A17: F01 | B17: Formulaire de contact simple | C17: Un formulaire qui vous envoie les demandes par e-mail. | D17: 0 | E17: 0 | F17: =IF(E17>0,D17/E17,"") | G17: inclus | H17: Inclus dans L01.
A18: F02 | B18: Formulaire avancé | C18: Demande de devis avec choix, pièces jointes, photos. | D18: 120 | E18: 2.5 | F18: =IF(E18>0,D18/E18,"") -> 48 | G18: par formulaire
A19: F03 | B19: Questionnaire guidé en plusieurs étapes | C19: Le visiteur répond étape par étape (ex. « Diagnostic Express » d'Hydr'eaux). | D19: 250 | E19: 5 | F19: =IF(E19>0,D19/E19,"") -> 50 | G19: par questionnaire
A20: F04 | B20: Prise de rendez-vous (outil existant) | C20: Intégration d'un agenda en ligne existant (Calendly, Google Agenda…). | D20: 90 | E20: 1.75 | F20: =IF(E20>0,D20/E20,"") -> 51.428571 | G20: forfait
A21: F05 | B21: Prise de rendez-vous sur mesure | C21: Votre propre système de réservation de créneaux, sans abonnement extérieur. | D21: 600 | E21: 12 | F21: =IF(E21>0,D21/E21,"") -> 50 | G21: forfait
A22: F06 | B22: Blog / actualités | C22: Une rubrique où publier des articles, avec catégories et recherche. | D22: 200 | E22: 4 | F22: =IF(E22>0,D22/E22,"") -> 50 | G22: forfait
A23: F07 | B23: Galerie / portfolio filtrable | C23: Vos réalisations en photos, triables par catégorie. | D23: 120 | E23: 2.5 | F23: =IF(E23>0,D23/E23,"") -> 48 | G23: forfait
A24: F08 | B24: FAQ avec recherche | C24: Questions fréquentes avec barre de recherche. | D24: 80 | E24: 1.5 | F24: =IF(E24>0,D24/E24,"") -> 53.333333 | G24: forfait
A25: F09 | B25: Carte interactive / zone d'intervention | C25: Une carte qui montre où vous intervenez. | D25: 90 | E25: 1.75 | F25: =IF(E25>0,D25/E25,"") -> 51.428571 | G25: forfait
A26: F10 | B26: Avis Google affichés | C26: Vos avis clients Google affichés sur le site. | D26: 90 | E26: 1.75 | F26: =IF(E26>0,D26/E26,"") -> 51.428571 | G26: forfait
A27: F11 | B27: Inscription à une newsletter | C27: Formulaire relié à un outil d'envoi d'e-mails. | D27: 90 | E27: 1.75 | F27: =IF(E27>0,D27/E27,"") -> 51.428571 | G27: forfait
A28: F12 | B28: Espace membre / client | C28: Connexion personnelle pour vos clients (documents, suivi…). | D28: 900 | E28: 18 | F28: =IF(E28>0,D28/E28,"") -> 50 | G28: forfait
A29: F13 | B29: Paiement en ligne simple | C29: Payer un acompte ou une prestation en ligne par carte. | D29: 200 | E29: 4 | F29: =IF(E29>0,D29/E29,"") -> 50 | G29: forfait | H29: Hors boutique.
A30: F14 | B30: Version dans une autre langue | C30: Le site disponible dans une langue de plus (traduction à part : C04). | D30: 350 | E30: 7 | F30: =IF(E30>0,D30/E30,"") -> 50 | G30: par langue
A31: F15 | B31: Mesure d'audience respectueuse du RGPD | C31: Statistiques de visites sans bandeau intrusif. | D31: 90 | E31: 1.75 | F31: =IF(E31>0,D31/E31,"") -> 51.428571 | G31: forfait
A32: F16 | B32: Bouton WhatsApp / appel / chat | C32: Un contact direct en un clic. | D32: 30 | E32: 0.5 | F32: =IF(E32>0,D32/E32,"") -> 60 | G32: forfait
A33: F17 | B33: Calculateur / simulateur sur mesure | C33: Un outil interactif pour vos clients (estimation de prix, configurateur…). | D33: 450 | E33: 9 | F33: =IF(E33>0,D33/E33,"") -> 50 | G33: par outil
A34: F18 | B34: Recherche interne | C34: Barre de recherche dans tout le site. | D34: 150 | E34: 3 | F34: =IF(E34>0,D34/E34,"") -> 50 | G34: forfait
A35: F19 | B35: Documents à télécharger | C35: Brochures, PDF, fiches techniques à télécharger. | D35: 60 | E35: 1.25 | F35: =IF(E35>0,D35/E35,"") -> 48 | G35: forfait
A36: F20 | B36: Fil Instagram / réseaux sociaux | C36: Vos dernières publications affichées sur le site. | D36: 80 | E36: 1.5 | F36: =IF(E36>0,D36/E36,"") -> 53.333333 | G36: forfait
A37: EFFETS ET ANIMATIONS SUR MESURE (en plus du niveau choisi)
A38: E01 | B38: Scène 3D sur mesure | C38: Un objet ou votre logo en 3D, animé et interactif. | D38: 700 | E38: 14 | F38: =IF(E38>0,D38/E38,"") -> 50 | G38: par scène | H38: Déjà incluse dans un accueil Immersif.
A39: E02 | B39: Démonstration interactive | C39: Une animation qui explique votre métier et avec laquelle on peut jouer. | D39: 250 | E39: 5 | F39: =IF(E39>0,D39/E39,"") -> 50 | G39: par animation
A40: E03 | B40: Transitions animées entre les pages | C40: Le passage d'une page à l'autre devient fluide et mis en scène. | D40: 180 | E40: 3.5 | F40: =IF(E40>0,D40/E40,"") -> 51.428571 | G40: forfait
A41: E04 | B41: Récit au défilement | C41: Une section qui se raconte au fur et à mesure qu'on descend. | D41: 220 | E41: 4.5 | F41: =IF(E41>0,D41/E41,"") -> 48.888889 | G41: par section
A42: E05 | B42: Vidéo d'arrière-plan / introduction | C42: Intégration d'une vidéo (le tournage et le montage ne sont pas compris). | D42: 90 | E42: 1.75 | F42: =IF(E42>0,D42/E42,"") -> 51.428571 | G42: par vidéo
...

Sheet Référencement
A1: Référencement : être trouvé sur Google et dans les IA
A2: Trois réglages : jusqu'où on veut être trouvé (portée), être cité par les IA, et des modules à la carte. Décrits par leur RÉSULTAT, jamais en pourcentage.
A4: A. PORTÉE : jusqu'où le client veut être trouvé (chaque niveau inclut le précédent)
A5: Niveau | B5: Objectif pour le client | C5: Ce qui est fait | D5: Forfait (€) | E5: Forfait (h) | F5: Par page (€) | G5: Par page (h) | H5: Par page en série (€) | I5: Par page en série (h) | J5: Suivi mensuel conseillé
A6: Aucun | B6: Pas de travail de référencement. | C6: Le site est en ligne, sans optimisation. | D6: 0 | E6: 0 | F6: 0 | G6: 0 | H6: 0 | I6: 0 | J6: —
A7: Essentiel | B7: Être trouvé quand on tape votre nom. | C7: Titres et descriptions de chaque page, plan du site déclaré à Google, site rapide et adapté au mobile, informations de l'entreprise structurées. | D7: 150 | E7: 3 | F7: 8 | G7: 0.15 | H7: 2 | I7: 0.05 | J7: Aucun ou publications
A8: Local | B8: Être trouvé dans votre ville et les communes autour. | C8: Essentiel + 20 à 40 mots-clés locaux choisis selon ce que les gens tapent vraiment, textes optimisés page par page, fiche Google Business, liens entre les pages. | D8: 350 | E8: 7 | F8: 15 | G8: 0.3 | H8: 6 | I8: 0.12 | J8: Suivi Local
A9: Régional | B9: Être trouvé dans tout votre département ou votre région, sur vos principaux services. | C9: Local + 80 à 150 mots-clés classés par volume de recherche, une page par service et par ville importante, analyse des concurrents, maillage complet, données structurées avancées. | D9: 650 | E9: 13 | F9: 30 | G9: 0.6 | H9: 10 | I9: 0.2 | J9: Suivi Régional
A10: National | B10: Être trouvé partout en France, sur tous vos services et sur les recherches les plus demandées. | C10: Régional + 200 mots-clés et plus, priorisés par volume et difficulté, architecture du site pensée pour Google, plan de contenus sur 12 mois, pages réponses aux questions fréquentes, stratégie de liens. | D10: 1200 | E10: 24 | F10: 50 | G10: 1 | H10: 15 | I10: 0.3 | J10: Suivi National
A12: B. VISIBILITÉ DANS LES IA : être cité par ChatGPT, Gemini, Perplexity et les résumés IA de Google
A13: Niveau | B13: Objectif pour le client | C13: Ce qui est fait | D13: Forfait (€) | E13: Forfait (h) | F13: Par page (€) | G13: Par page (h) | J13: Suivi mensuel conseillé
A14: Aucune | B14: Pas de travail spécifique pour les IA. | D14: 0 | E14: 0 | F14: 0 | G14: 0 | J14: —
A15: Essentielle | B15: Que les IA comprennent qui vous êtes et ce que vous faites. | C15: Fichier llms.txt, données structurées complètes (entreprise, services, FAQ, avis), informations identiques partout (nom, adresse, horaires), contenus rédigés en questions-réponses. | D15: 150 | E15: 3 | F15: 5 | G15: 0.1 | J15: Aucun
A16: Avancée | B16: Que les IA vous citent quand on leur demande un professionnel comme vous. | C16: Essentielle + pages réponses dédiées aux questions de vos clients, présence sur les sources que lisent les IA (annuaires, avis, presse locale), tests réguliers des réponses des IA sur vos recherches. | D16: 400 | E16: 8 | F16: 15 | G16: 0.3 | J16: Suivi IA
A18: C. MODULES À LA CARTE (en plus du niveau choisi, ou pour un site existant)
A19: Code | B19: Élément | C19: Ce que ça veut dire pour le client | D19: Prix (€) | E19: Temps estimé (h) | F19: €/h effectif | G19: Unité | H19: Note interne
A20: S01 | B20: Audit de référencement de départ | C20: Où vous en êtes sur Google, vos concurrents, vos points faibles, les priorités. | D20: 150 | E20: 3 | F20: =IF(E20>0,D20/E20,"") -> 50 | G20: forfait
A21: S02 | B21: Étude de mots-clés approfondie | C21: Ce que vos clients tapent vraiment, combien de fois par mois, et ce qui est atteignable. | D21: 200 | E21: 4 | F21: =IF(E21>0,D21/E21,"") -> 50 | G21: forfait | H21: Incluse dans les niveaux Régional et National.
A22: S03 | B22: Page service optimisée supplémentaire | C22: Une page dédiée à un service, rédaction comprise. | D22: 90 | E22: 1.75 | F22: =IF(E22>0,D22/E22,"") -> 51.428571 | G22: par page
A23: S04 | B23: Page ville optimisée supplémentaire | C23: Une page pour une ville ou un secteur, rédaction comprise. | D23: 45 | E23: 0.9 | F23: =IF(E23>0,D23/E23,"") -> 50 | G23: par page
A24: S05 | B24: Données structurées avancées | C24: Avis, produits, événements, FAQ affichés directement dans Google. | D24: 120 | E24: 2.5 | F24: =IF(E24>0,D24/E24,"") -> 48 | G24: forfait
A25: S06 | B25: Optimisation de la vitesse (Core Web Vitals) | C25: Les critères de vitesse que Google mesure. | D25: 150 | E25: 3 | F25: =IF(E25>0,D25/E25,"") -> 50 | G25: forfait
A26: S07 | B26: Optimisation des images | C26: Noms, textes alternatifs, poids allégé. | D26: 40 | E26: 0.75 | F26: =IF(E26>0,D26/E26,"") -> 53.333333 | G26: par lot de 50
A27: S08 | B27: Inscription dans les annuaires | C27: Pages Jaunes, annuaires locaux et professionnels, avec informations identiques partout. | D27: 120 | E27: 2.5 | F27: =IF(E27>0,D27/E27,"") -> 48 | G27: par lot de 20
A28: S09 | B28: Obtention d'un lien vers votre site | C28: Un site sérieux qui parle de vous et renvoie vers le vôtre (partenaire, article, presse locale). | D28: 80 | E28: 1.5 | F28: =IF(E28>0,D28/E28,"") -> 53.333333 | G28: par lien
A29: S10 | B29: Outils Google et Bing configurés | C29: Search Console, Bing Webmaster, statistiques. | D29: 60 | E29: 1.25 | F29: =IF(E29>0,D29/E29,"") -> 48 | G29: forfait
A30: S11 | B30: Référencement des fiches produits | C30: Titres, descriptions et données de chaque produit de la boutique. | D30: 4 | E30: 0.08 | F30: =IF(E30>0,D30/E30,"") -> 50 | G30: par produit
A31: S12 | B31: Référencement dans une autre langue | D31: 150 | E31: 3 | F31: =IF(E31>0,D31/E31,"") -> 50 | G31: par langue
A32: S13 | B32: Refonte sans perte de référencement | C32: Redirections et vérifications pour garder vos positions quand on remplace un ancien site. | D32: 200 | E32: 4 | F32: =IF(E32>0,D32/E32,"") -> 50 | G32: forfait
A35: Pourquoi pas un pourcentage ? « Référencé à 70 % » ne veut rien dire (et 100 % n'existe pas). Un niveau décrit par son résultat (« être trouvé dans tout mon département ») se comprend et se compare.
A36: Aucun positionnement ni aucune citation par une IA n'est garanti : cela dépend de la concurrence, du temps et des moteurs. À rappeler dans chaque devis.

Sheet Boutique
A1: Boutique en ligne
A2: S'ajoute au site (forfait de lancement + accueil + pages). On compte les PRODUITS (fiches) et les VARIANTES, jamais le stock.
A4: Code | B4: Élément | C4: Ce que ça veut dire pour le client | D4: Prix (€) | E4: Temps estimé (h) | F4: €/h effectif | G4: Unité | H4: Note interne
A5: BASE
A6: B00 | B6: Socle boutique | C6: Panier, paiement par carte, comptes clients, e-mails automatiques (commande, expédition), livraison simple, conditions générales de vente. | D6: 1100 | E6: 20 | F6: =IF(E6>0,D6/E6,"") -> 55 | G6: forfait
A7: CATALOGUE
A8: B01 | B8: Mise en ligne d'un produit | C8: On crée la fiche produit (photos, texte, prix) à partir de vos informations. | D8: 3 | E8: 0.06 | F8: =IF(E8>0,D8/E8,"") -> 50 | G8: par produit | H8: Un produit = une fiche, même si vous en avez 200 en stock.
A9: B02 | B9: Import du catalogue depuis un fichier | C9: Vous avez déjà la liste de vos produits (Excel, ancien site) : on l'importe d'un coup. | D9: 120 | E9: 2.5 | F9: =IF(E9>0,D9/E9,"") -> 48 | G9: forfait | H9: Remplace B01 si le client fournit un fichier propre.
A10: B03 | B10: Variante de produit | C10: Une déclinaison d'un produit : taille, couleur, contenance… | D10: 0.5 | E10: 0.01 | F10: =IF(E10>0,D10/E10,"") -> 50 | G10: par variante | H10: Ex. un t-shirt en 3 couleurs × 4 tailles = 12 variantes.
A11: B04 | B11: Catégorie supplémentaire | C11: Au-delà des catégories incluses (voir Paramètres). | D11: 15 | E11: 0.3 | F11: =IF(E11>0,D11/E11,"") -> 50 | G11: par catégorie
A12: OPTIONS
A13: B05 | B13: Click & collect | C13: Commander en ligne, retirer en boutique. | D13: 150 | E13: 3 | F13: =IF(E13>0,D13/E13,"") -> 50 | G13: forfait
A14: B06 | B14: Points relais / plusieurs transporteurs | C14: Choix du mode de livraison et calcul des frais. | D14: 200 | E14: 4 | F14: =IF(E14>0,D14/E14,"") -> 50 | G14: forfait
A15: B07 | B15: Abonnement / box récurrente | C15: Le client paie tous les mois automatiquement. | D15: 400 | E15: 8 | F15: =IF(E15>0,D15/E15,"") -> 50 | G15: forfait
A16: B08 | B16: Produits numériques | C16: Fichiers téléchargeables après achat. | D16: 150 | E16: 3 | F16: =IF(E16>0,D16/E16,"") -> 50 | G16: forfait
A17: B09 | B17: Tarifs professionnels | C17: Prix différents pour les clients pros. | D17: 300 | E17: 6 | F17: =IF(E17>0,D17/E17,"") -> 50 | G17: forfait
A18: B10 | B18: Synchronisation des stocks | C18: Stocks reliés à votre caisse ou à votre logiciel. | D18: 450 | E18: 9 | F18: =IF(E18>0,D18/E18,"") -> 50 | G18: par logiciel | H18: Selon le logiciel : à confirmer au devis.
A19: B11 | B19: Avis clients sur les produits | D19: 80 | E19: 1.5 | F19: =IF(E19>0,D19/E19,"") -> 53.333333 | G19: forfait
A20: B12 | B20: Codes promo avancés et fidélité | D20: 150 | E20: 3 | F20: =IF(E20>0,D20/E20,"") -> 50 | G20: forfait
A21: B13 | B21: Google Shopping | C21: Vos produits affichés dans l'onglet Shopping de Google. | D21: 150 | E21: 3 | F21: =IF(E21>0,D21/E21,"") -> 50 | G21: forfait
A22: B14 | B22: Cartes cadeaux | D22: 120 | E22: 2.5 | F22: =IF(E22>0,D22/E22,"") -> 48 | G22: forfait

Sheet Outil de gestion
A1: Outil de gestion sur mesure
A2: Un socle + les modules choisis + les options. Le prix des modules augmente avec le nombre d'utilisateurs.
A4: Code | B4: Élément | C4: Ce que ça veut dire pour le client | D4: Prix (€) | E4: Temps estimé (h) | F4: €/h effectif | G4: Unité | H4: Note interne
A5: SOCLE
A6: O00 | B6: Socle de l'outil | C6: Connexion sécurisée, base de données, tableau de bord, export de vos données, hébergement prêt. | D6: 900 | E6: 18 | F6: =IF(E6>0,D6/E6,"") -> 50 | G6: forfait | H6: Toujours compté si outil.
A7: MODULES — GESTION COMMERCIALE
A8: O01 | B8: Clients / contacts (CRM) | C8: Fiches clients, historique, notes, relances. | D8: 350 | E8: 7 | F8: =IF(E8>0,D8/E8,"") -> 50 | G8: module
A9: O02 | B9: Devis | C9: Créer, envoyer et suivre vos devis. | D9: 400 | E9: 8 | F9: =IF(E9>0,D9/E9,"") -> 50 | G9: module
A10: O03 | B10: Factures | C10: Factures conformes, numérotation automatique, avoirs. | D10: 450 | E10: 9 | F10: =IF(E10>0,D10/E10,"") -> 50 | G10: module | H10: Devis→facture inclus si O02 + O03.
A11: O04 | B11: Suivi des paiements et relances | C11: Qui a payé, qui est en retard, relances automatiques. | D11: 250 | E11: 5 | F11: =IF(E11>0,D11/E11,"") -> 50 | G11: module
A12: O05 | B12: Commandes fournisseurs | D12: 350 | E12: 7 | F12: =IF(E12>0,D12/E12,"") -> 50 | G12: module
A13: O06 | B13: Catalogue de prestations / produits | C13: Vos prix et prestations réutilisables partout. | D13: 200 | E13: 4 | F13: =IF(E13>0,D13/E13,"") -> 50 | G13: module
A14: MODULES — ORGANISATION
A15: O07 | B15: Planning / agenda d'équipe | C15: Qui fait quoi, quand. | D15: 450 | E15: 9 | F15: =IF(E15>0,D15/E15,"") -> 50 | G15: module
A16: O08 | B16: Prise de rendez-vous par vos clients | C16: Vos clients réservent un créneau en ligne. | D16: 400 | E16: 8 | F16: =IF(E16>0,D16/E16,"") -> 50 | G16: module
A17: O09 | B17: Réservations / locations | C17: Réserver des salles, véhicules, matériel, chambres… | D17: 500 | E17: 10 | F17: =IF(E17>0,D17/E17,"") -> 50 | G17: module
A18: O10 | B18: Interventions / chantiers | C18: Suivi des chantiers, photos, rapports d'intervention. | D18: 500 | E18: 10 | F18: =IF(E18>0,D18/E18,"") -> 50 | G18: module
A19: O11 | B19: Feuilles de temps / pointage | D19: 300 | E19: 6 | F19: =IF(E19>0,D19/E19,"") -> 50 | G19: module
A20: O12 | B20: Congés et équipe | C20: Demandes de congés, échanges de créneaux. | D20: 350 | E20: 7 | F20: =IF(E20>0,D20/E20,"") -> 50 | G20: module
A21: O13 | B21: Notes de frais | D21: 250 | E21: 5 | F21: =IF(E21>0,D21/E21,"") -> 50 | G21: module
A22: O14 | B22: Véhicules et matériel | C22: Entretien, disponibilité, affectation. | D22: 300 | E22: 6 | F22: =IF(E22>0,D22/E22,"") -> 50 | G22: module
A23: MODULES — VENTE ET RELATION CLIENT
A24: O15 | B24: Caisse / encaissement | D24: 600 | E24: 12 | F24: =IF(E24>0,D24/E24,"") -> 50 | G24: module | H24: Vérifier les obligations légales des logiciels de caisse avant de vendre ce module.
A25: O16 | B25: Stocks | C25: Entrées, sorties, alertes de rupture. | D25: 450 | E25: 9 | F25: =IF(E25>0,D25/E25,"") -> 50 | G25: module
A26: O17 | B26: Commandes en ligne / click & collect | D26: 450 | E26: 9 | F26: =IF(E26>0,D26/E26,"") -> 50 | G26: module
A27: O18 | B27: Fidélité | C27: Points, récompenses, offres. | D27: 300 | E27: 6 | F27: =IF(E27>0,D27/E27,"") -> 50 | G27: module
A28: O19 | B28: Menu / carte en ligne avec QR code | D28: 250 | E28: 5 | F28: =IF(E28>0,D28/E28,"") -> 50 | G28: module | H28: Restaurants.
A29: O20 | B29: Espace client (portail) | C29: Vos clients consultent devis, factures, documents. | D29: 600 | E29: 12 | F29: =IF(E29>0,D29/E29,"") -> 50 | G29: module
A30: MODULES — MÉTIERS SPÉCIFIQUES
A31: O21 | B31: Dossiers clients détaillés (santé, animaux, élèves…) | C31: Fiches de suivi propres à votre métier. | D31: 500 | E31: 10 | F31: =IF(E31>0,D31/E31,"") -> 50 | G31: module
A32: O22 | B32: Adhérents, cours et abonnements | C32: Salles de sport, écoles, associations. | D32: 450 | E32: 9 | F32: =IF(E32>0,D32/E32,"") -> 50 | G32: module
A33: O23 | B33: Cotisations d'association | D33: 300 | E33: 6 | F33: =IF(E33>0,D33/E33,"") -> 50 | G33: module
A34: O24 | B34: Traçabilité / hygiène (HACCP) | C34: Relevés de température, contrôles, registres. | D34: 400 | E34: 8 | F34: =IF(E34>0,D34/E34,"") -> 50 | G34: module
A35: O25 | B35: Formulaires de terrain | C35: Rapports, check-lists, signatures remplis sur téléphone. | D35: 400 | E35: 8 | F35: =IF(E35>0,D35/E35,"") -> 50 | G35: module
A36: MODULES — PILOTAGE
A37: O26 | B37: Tableau de bord avancé | C37: Chiffre d'affaires, marges, objectifs, graphiques. | D37: 350 | E37: 7 | F37: =IF(E37>0,D37/E37,"") -> 50 | G37: module
A38: O27 | B38: Rapports PDF automatiques | D38: 300 | E38: 6 | F38: =IF(E38>0,D38/E38,"") -> 50 | G38: module
A39: O28 | B39: Documents partagés | C39: Classement de vos fichiers par client ou dossier. | D39: 250 | E39: 5 | F39: =IF(E39>0,D39/E39,"") -> 50 | G39: module
A40: O29 | B40: Notifications et messagerie interne | D40: 250 | E40: 5 | F40: =IF(E40>0,D40/E40,"") -> 50 | G40: module
A41: O30 | B41: Signature électronique | C41: Via un service spécialisé (coût d'usage refacturé). | D41: 250 | E41: 5 | F41: =IF(E41>0,D41/E41,"") -> 50 | G41: module
...

Sheet Abonnements
A1: Abonnements mensuels (calculés, sans engagement, préavis d'un mois)
A2: L'abonnement n'est pas une formule fixe : il se compose à partir de ces briques. Le Simulateur fait le calcul.
A4: Code | B4: Élément | C4: Ce que ça veut dire pour le client | D4: Prix (€) | E4: Temps estimé (h) | F4: €/h effectif | G4: Unité | H4: Note interne
A5: HÉBERGEMENT (nom de domaine inclus à partir de la 2e année)
A6: A01 | B6: Hébergement site jusqu'à 10 pages | C6: Serveur, nom de domaine, sécurité https, sauvegardes. | D6: 10 | E6: 0 | F6: =IF(E6>0,D6/E6,"") | G6: par mois
A7: A02 | B7: Hébergement site de plus de 10 pages | D7: 15 | E7: 0 | F7: =IF(E7>0,D7/E7,"") | G7: par mois
A8: A03 | B8: Supplément site Immersif (3D) | C8: Ressources plus lourdes à diffuser. | D8: 5 | E8: 0 | F8: =IF(E8>0,D8/E8,"") | G8: par mois
A9: A04 | B9: Hébergement boutique | D9: 25 | E9: 0 | F9: =IF(E9>0,D9/E9,"") | G9: par mois
A10: A05 | B10: Hébergement outil de gestion | C10: Base de données et sauvegardes renforcées. | D10: 30 | E10: 0 | F10: =IF(E10>0,D10/E10,"") | G10: par mois
A11: MAINTENANCE ET SÉCURITÉ
A12: A06 | B12: Maintenance site — base | C12: Mises à jour, surveillance, correction des anomalies, petites retouches. | D12: 15 | E12: 0.25 | F12: =IF(E12>0,D12/E12,"") -> 60 | G12: par mois
A13: A07 | B13: Maintenance — par page | D13: 0.5 | E13: 0.01 | F13: =IF(E13>0,D13/E13,"") -> 50 | G13: par page / mois
A14: A08 | B14: Maintenance — par page en série | D14: 0.1 | E14: 0 | F14: =IF(E14>0,D14/E14,"") | G14: par page / mois
A15: A09 | B15: Maintenance boutique | C15: Vérification des paiements, commandes, e-mails. | D15: 15 | E15: 0.25 | F15: =IF(E15>0,D15/E15,"") -> 60 | G15: par mois
A16: A10 | B16: Maintenance outil — base | D16: 20 | E16: 0.4 | F16: =IF(E16>0,D16/E16,"") -> 50 | G16: par mois
A17: A11 | B17: Maintenance outil — par module | D17: 5 | E17: 0.1 | F17: =IF(E17>0,D17/E17,"") -> 50 | G17: par module / mois
A18: CONTENUS ET VISIBILITÉ
A19: A12 | B19: Publication courte | C19: Une réalisation, une actualité, un conseil, à partir de vos photos et infos. | D19: 10 | E19: 0.2 | F19: =IF(E19>0,D19/E19,"") -> 50 | G19: par publication
A20: A13 | B20: Article de blog optimisé | D20: 40 | E20: 0.8 | F20: =IF(E20>0,D20/E20,"") -> 50 | G20: par article
A21: A14 | B21: Suivi référencement Local | C21: Suivi Google Search Console, améliorations mois par mois, conseils. | D21: 60 | E21: 1.25 | F21: =IF(E21>0,D21/E21,"") -> 48 | G21: par mois
A22: A15 | B22: Suivi référencement Régional | C22: Suivi Local + nouvelles pages ciblées, analyse des concurrents. | D22: 120 | E22: 2.5 | F22: =IF(E22>0,D22/E22,"") -> 48 | G22: par mois
A23: A20 | B23: Suivi référencement National | C23: Suivi Régional + plan de contenus, positions sur les recherches les plus demandées. | D23: 220 | E23: 4.5 | F23: =IF(E23>0,D23/E23,"") -> 48.888889 | G23: par mois
A24: A21 | B24: Suivi de la visibilité dans les IA | C24: Tests mensuels des réponses de ChatGPT, Gemini, Perplexity et Google sur vos recherches ; ajustements. | D24: 40 | E24: 0.8 | F24: =IF(E24>0,D24/E24,"") -> 50 | G24: par mois
A25: A22 | B25: Lien obtenu vers votre site | C25: Un nouveau site sérieux qui renvoie vers le vôtre. | D25: 80 | E25: 1.5 | F25: =IF(E25>0,D25/E25,"") -> 53.333333 | G25: par lien
A26: A16 | B26: Suivi de la fiche Google Business | C26: Publications, réponses aux avis, mises à jour. | D26: 25 | E26: 0.5 | F26: =IF(E26>0,D26/E26,"") -> 50 | G26: par mois
A27: A17 | B27: Rapport mensuel | C27: Visites, demandes reçues, évolution, en une page lisible. | D27: 15 | E27: 0.3 | F27: =IF(E27>0,D27/E27,"") -> 50 | G27: par mois | H27: Nécessite F15.
A28: A18 | B28: Heure de modifications incluse | C28: Temps réservé chaque mois pour vos demandes de changements. | D28: 35 | E28: 1 | F28: =IF(E28>0,D28/E28,"") -> 35 | G28: par heure / mois | H28: Moins cher que l'heure ponctuelle (40 €).
A29: REMISE
A30: A19 | B30: Remise en cas de paiement annuel | D30: 0.1 | E30: 0 | F30: =IF(E30>0,D30/E30,"") | G30: % du total | H30: Valeur en pourcentage.

Sheet À la carte
A1: Services à la carte
A2: Pour les clients qui ont déjà un site, ou pour les extras avant, pendant ou après un projet.
A4: Code | B4: Élément | C4: Ce que ça veut dire pour le client | D4: Prix (€) | E4: Temps estimé (h) | F4: €/h effectif | G4: Unité | H4: Note interne
A5: POUR UN SITE EXISTANT
A6: K01 | B6: Audit de votre site actuel | C6: Rapport clair : ce qui marche, ce qui bloque, quoi améliorer en priorité. | D6: 90 | E6: 2 | F6: =IF(E6>0,D6/E6,"") -> 45 | G6: forfait
A7: K02 | B7: Intervention technique | C7: Correction, ajout, modification sur un site existant. | D7: 40 | E7: 1 | F7: =IF(E7>0,D7/E7,"") -> 40 | G7: par heure | H7: Minimum 30 min.
A8: K03 | B8: Accélération du site | C8: Optimisation de la vitesse de chargement. | D8: 180 | E8: 3.5 | F8: =IF(E8>0,D8/E8,"") -> 51.428571 | G8: forfait
A9: K04 | B9: Mise en conformité légale | C9: Mentions légales, confidentialité, cookies. | D9: 120 | E9: 2.5 | F9: =IF(E9>0,D9/E9,"") -> 48 | G9: forfait
A10: K05 | B10: Transfert d'hébergement | C10: Déplacer un site existant vers un hébergement géré par Stackup. | D10: 150 | E10: 3 | F10: =IF(E10>0,D10/E10,"") -> 50 | G10: forfait
A11: K06 | B11: Création de la fiche Google Business | D11: 90 | E11: 1.75 | F11: =IF(E11>0,D11/E11,"") -> 51.428571 | G11: forfait
A12: K07 | B12: Adresses e-mail professionnelles | C12: Configuration (le coût du service e-mail reste à votre charge). | D12: 60 | E12: 1.25 | F12: =IF(E12>0,D12/E12,"") -> 48 | G12: forfait
A13: K08 | B13: Refonte d'un site existant | C13: Se calcule avec la grille de création (même prix que du neuf, moins la reprise de contenu). | D13: 0 | E13: 0 | F13: =IF(E13>0,D13/E13,"") | G13: voir Simulateur
A14: AVANT / PENDANT / APRÈS
A15: K09 | B15: Formation à l'utilisation du site ou de l'outil | D15: 40 | E15: 1 | F15: =IF(E15>0,D15/E15,"") -> 40 | G15: par heure
A16: K10 | B16: Rendez-vous de conseil stratégique (1 h 30) | C16: Analyse de vos besoins, recommandations concrètes. | D16: 90 | E16: 1.5 | F16: =IF(E16>0,D16/E16,"") -> 60 | G16: forfait | H16: Le travail qui en découle est facturé à part.
A17: K11 | B17: Livraison en urgence (< 48 h) | C17: Pour une intervention ponctuelle. | D17: 0.3 | E17: 0 | F17: =IF(E17>0,D17/E17,"") | G17: % de majoration | H17: Valeur en pourcentage.
A18: K12 | B18: Intervention hors horaires (soir, week-end) | D18: 0.5 | E18: 0 | F18: =IF(E18>0,D18/E18,"") | G18: % de majoration | H18: Valeur en pourcentage.
A19: K13 | B19: Retrait de la mention « Réalisé par Stackup » | D19: 0 | E19: 0 | F19: =IF(E19>0,D19/E19,"") | G19: gratuit | H19: Gratuit : la faire payer donne une mauvaise image.
A20: K14 | B20: Nom de domaine supplémentaire | D20: 0 | E20: 0 | F20: =IF(E20>0,D20/E20,"") | G20: au coût réel
A21: K15 | B21: Campagne e-mail / newsletter | C21: Rédaction et envoi d'une campagne. | D21: 120 | E21: 2.5 | F21: =IF(E21>0,D21/E21,"") -> 48 | G21: par campagne

Sheet Contrat
A1: Ce que tu t'engages à faire (et à ne pas faire)
A2: Check-list des points à faire figurer dans tes devis et CGV. À faire relire par un juriste.
A4: Point | B4: Ce qu'on écrit | C4: Statut
A5: Identité | B5: Nom + « EI » (obligatoire pour un entrepreneur individuel), adresse, SIRET, e-mail, sur chaque devis et facture. | C5: À compléter dès le SIRET reçu
A6: TVA | B6: « TVA non applicable, art. 293 B du CGI » tant que tu es en franchise. | C6: À vérifier chaque année
A7: Validité du devis | B7: 30 jours. | C7: Repris de tes devis
A8: Lancement | B8: Commande ferme à la signature du devis et à l'encaissement de l'acompte. | C8: Repris de tes devis
A9: Acompte et échéancier | B9: 40 % à la signature ; solde à la livraison (2 fois) ou 30 % à la maquette + 30 % à la livraison (3 fois) ; 4 fois au-delà du seuil (Paramètres). | C9: Repris + 4 fois ajouté
A10: Démo et visio | B10: Démo 15 € et visio 30 € facturées à part, non remboursables. La démo reste ta propriété si le client ne signe pas. | C10: Nouveau
A11: Rendez-vous inclus | B11: 3 rendez-vous de finalisation ; au-delà 40 €/h. | C11: Nouveau — remplace « nombre non fixé »
A12: Modifications incluses | B12: 2 séries de retours sur la maquette ; puis mois d'ajustements après la mise en ligne. | C12: Nouveau
A13: Calendrier | B13: Délai indicatif, suspendu tant que le client n'a pas fourni contenus, informations ou validations. | C13: Repris de tes devis
A14: Contenus | B14: Le client fournit textes, photos, logos, en garantit les droits et l'exactitude. | C14: Repris
A15: Livraison et réception | B15: Lien de prévisualisation ; 14 jours pour émettre des réserves écrites ; sinon réception tacite, solde exigible. | C15: Repris
... A27: Force majeure | B27: Clause standard. | C27: À ajouter
